Traceback (most recent call last):
  File "/Users/maxandchang/Documents/JupyterBook/jupyterbook/lib/python3.7/site-packages/nbclient/client.py", line 778, in _async_poll_for_reply
    msg = await ensure_async(self.kc.shell_channel.get_msg(timeout=new_timeout))
  File "/Users/maxandchang/Documents/JupyterBook/jupyterbook/lib/python3.7/site-packages/jupyter_core/utils/__init__.py", line 110, in ensure_async
    result = await obj
  File "/Users/maxandchang/Documents/JupyterBook/jupyterbook/lib/python3.7/site-packages/jupyter_client/channels.py", line 230, in get_msg
    raise Empty
_queue.Empty

During handling of the above exception, another exception occurred:

Traceback (most recent call last):
  File "/Users/maxandchang/Documents/JupyterBook/jupyterbook/lib/python3.7/site-packages/jupyter_cache/executors/utils.py", line 64, in single_nb_execution
    **kwargs,
  File "/Users/maxandchang/Documents/JupyterBook/jupyterbook/lib/python3.7/site-packages/nbclient/client.py", line 1305, in execute
    return NotebookClient(nb=nb, resources=resources, km=km, **kwargs).execute()
  File "/Users/maxandchang/Documents/JupyterBook/jupyterbook/lib/python3.7/site-packages/jupyter_core/utils/__init__.py", line 98, in wrapped
    return loop.run_until_complete(inner)
  File "/Users/maxandchang/anaconda3/lib/python3.7/asyncio/base_events.py", line 587, in run_until_complete
    return future.result()
  File "/Users/maxandchang/Documents/JupyterBook/jupyterbook/lib/python3.7/site-packages/nbclient/client.py", line 706, in async_execute
    cell, index, execution_count=self.code_cells_executed + 1
  File "/Users/maxandchang/Documents/JupyterBook/jupyterbook/lib/python3.7/site-packages/nbclient/client.py", line 1001, in async_execute_cell
    exec_reply = await self.task_poll_for_reply
  File "/Users/maxandchang/Documents/JupyterBook/jupyterbook/lib/python3.7/site-packages/nbclient/client.py", line 802, in _async_poll_for_reply
    error_on_timeout_execute_reply = await self._async_handle_timeout(timeout, cell)
  File "/Users/maxandchang/Documents/JupyterBook/jupyterbook/lib/python3.7/site-packages/nbclient/client.py", line 853, in _async_handle_timeout
    "Cell execution timed out", timeout, cell
nbclient.exceptions.CellTimeoutError: A cell timed out while it was being executed, after 30 seconds.
The message was: Cell execution timed out.
Here is a preview of the cell contents:
-------------------
["# Group by 'user_id'", "grouped = data_merge2.groupby('user_id')", '# Define a function to calculate the day difference', 'start_date = dt.datetime(2023,9,1)', 'today_date = dt.datetime(2024,3,25)']
...
["data_merge2['week'] = data_merge2['week'] + 1", '', '# Calculate the number of transaction opportunities', "data_merge2['n_weeks'] = (( today_date - data_merge2['install_date']).dt.days // 7) + 1", 'data_merge2.head()']
-------------------

